Workbook

Sheet Start Here
B2: Brooks Stevens — Interim Time, Billing & Financials Workbook
B3: Ajera bridge workbook — start capturing time and billing today while the permanent system is selected.
B5: How to use this workbook
B6: 1. Fill in the three yellow SETUP tabs first: Employees, Projects, Indirect Codes.
B7: 2. Everyone logs hours on the TIME ENTRY tab — one row per project/task per day.
B8: 3. The blue REPORT tabs (Project Summary, Utilization, Dashboard) update automatically.
B9: 4. Raise invoices on the INVOICES tab; unbilled $ per project is calculated for you.
B11: Legend
B12: YELLOW cells = you type here (setup + time entry).
B13: WHITE/grey cells with formulas = calculated automatically — do not overtype.
B14: Dropdowns pull from the setup tabs, so set those up before entering time.
B16: What this covers vs. Ajera
... B26: Prepared for Brooks Stevens Inc. • Michael Hopkins • Interim workbook v1

Sheet Dashboard
B2: Firm Dashboard — live snapshot
B4: Total Billable $ (all projects) | C4: ='Project Summary'!$F$64 -> 942.5 | E4: Total Hours Logged | F4: =Utilization!$B$44 -> 6.5
B5: Total Cost $ | C5: ='Project Summary'!$G$64 -> 442 | E5: Billable Hours | F5: =Utilization!$C$44 -> 6.5
B6: Gross Margin $ | C6: ='Project Summary'!$H$64 -> 500.5 | E6: Indirect Hours | F6: =Utilization!$D$44 -> 0
B7: Gross Margin % | C7: =IF('Project Summary'!$F$64=0,"",'Project Summary'!$H$64/'Project Summary'!$F$64) -> 0.53103448 | E7: Firm Utilization % | F7: =Utilization!$E$44 -> 1
B8: Total Invoiced $ | C8: =Invoices!$G$204 -> 900 | E8: Active Projects | F8: =COUNTIF(Projects!$C$4:$C$63,"?*") -> 1
B9: WIP (Unbilled) $ | C9: ='Project Summary'!$J$64 -> 42.5 | E9: Active Employees | F9: =COUNTIF(Employees!$B$4:$B$43,"?*") -> 1
B11: Numbers populate automatically as setup tabs and Time Entry are filled in.

Sheet Time Entry
A1: Time Entry
A2: One row per person, per charge, per day. Yellow = you enter. White = auto. Pick Employee and Project/Code from the dropdowns.
A3: Date | B3: Week Ending | C3: Employee | D3: Charge Type | E3: Project / Code | F3: Phase | G3: Hours | H3: Billable? | I3: Bill Rate | J3: Billable $ | K3: Cost $ | L3: Notes
A4: 2026-08-04 | B4: =IF(A4="","",A4+7-WEEKDAY(A4,1)+1) -> 46243 | C4: Jane Designer | D4: Project | E4: Handlebar Control Module Redesign | F4: Concept | G4: 6.5 | H4: =IF(E4="","",IFERROR(INDEX(Lists!$C$2:$C$86,MATCH(E4,Lists!$A$2:$A$86,0)),"?")) -> Yes | I4: =IF(OR(C4="",E4=""),"",IF(H4="Yes",IFERROR(INDEX(Employees!$E$4:$E$43,MATCH(C4,Employees!$B$4:$B$43,0)),0),0)) -> 145 | J4: =IF(G4="","",IF(H4="Yes",G4*I4,0)) -> 942.5 | K4: =IF(OR(C4="",G4=""),"",G4*IFERROR(INDEX(Employees!$F$4:$F$43,MATCH(C4,Employees!$B$4:$B$43,0)),0)) -> 442 | L4: Concept sketches + DFM review
B5: =IF(A5="","",A5+7-WEEKDAY(A5,1)+1) | H5: =IF(E5="","",IFERROR(INDEX(Lists!$C$2:$C$86,MATCH(E5,Lists!$A$2:$A$86,0)),"?")) | I5: =IF(OR(C5="",E5=""),"",IF(H5="Yes",IFERROR(INDEX(Employees!$E$4:$E$43,MATCH(C5,Employees!$B$4:$B$43,0)),0),0)) | J5: =IF(G5="","",IF(H5="Yes",G5*I5,0)) | K5: =IF(OR(C5="",G5=""),"",G5*IFERROR(INDEX(Employees!$F$4:$F$43,MATCH(C5,Employees!$B$4:$B$43,0)),0))
B6: =IF(A6="","",A6+7-WEEKDAY(A6,1)+1) | H6: =IF(E6="","",IFERROR(INDEX(Lists!$C$2:$C$86,MATCH(E6,Lists!$A$2:$A$86,0)),"?")) | I6: =IF(OR(C6="",E6=""),"",IF(H6="Yes",IFERROR(INDEX(Employees!$E$4:$E$43,MATCH(C6,Employees!$B$4:$B$43,0)),0),0)) | J6: =IF(G6="","",IF(H6="Yes",G6*I6,0)) | K6: =IF(OR(C6="",G6=""),"",G6*IFERROR(INDEX(Employees!$F$4:$F$43,MATCH(C6,Employees!$B$4:$B$43,0)),0))
B7: =IF(A7="","",A7+7-WEEKDAY(A7,1)+1) | H7: =IF(E7="","",IFERROR(INDEX(Lists!$C$2:$C$86,MATCH(E7,Lists!$A$2:$A$86,0)),"?")) | I7: =IF(OR(C7="",E7=""),"",IF(H7="Yes",IFERROR(INDEX(Employees!$E$4:$E$43,MATCH(C7,Employees!$B$4:$B$43,0)),0),0)) | J7: =IF(G7="","",IF(H7="Yes",G7*I7,0)) | K7: =IF(OR(C7="",G7=""),"",G7*IFERROR(INDEX(Employees!$F$4:$F$43,MATCH(C7,Employees!$B$4:$B$43,0)),0))
B8: =IF(A8="","",A8+7-WEEKDAY(A8,1)+1) | H8: =IF(E8="","",IFERROR(INDEX(Lists!$C$2:$C$86,MATCH(E8,Lists!$A$2:$A$86,0)),"?")) | I8: =IF(OR(C8="",E8=""),"",IF(H8="Yes",IFERROR(INDEX(Employees!$E$4:$E$43,MATCH(C8,Employees!$B$4:$B$43,0)),0),0)) | J8: =IF(G8="","",IF(H8="Yes",G8*I8,0)) | K8: =IF(OR(C8="",G8=""),"",G8*IFERROR(INDEX(Employees!$F$4:$F$43,MATCH(C8,Employees!$B$4:$B$43,0)),0))
B9: =IF(A9="","",A9+7-WEEKDAY(A9,1)+1) | H9: =IF(E9="","",IFERROR(INDEX(Lists!$C$2:$C$86,MATCH(E9,Lists!$A$2:$A$86,0)),"?")) | I9: =IF(OR(C9="",E9=""),"",IF(H9="Yes",IFERROR(INDEX(Employees!$E$4:$E$43,MATCH(C9,Employees!$B$4:$B$43,0)),0),0)) | J9: =IF(G9="","",IF(H9="Yes",G9*I9,0)) | K9: =IF(OR(C9="",G9=""),"",G9*IFERROR(INDEX(Employees!$F$4:$F$43,MATCH(C9,Employees!$B$4:$B$43,0)),0))
B10: =IF(A10="","",A10+7-WEEKDAY(A10,1)+1) | H10: =IF(E10="","",IFERROR(INDEX(Lists!$C$2:$C$86,MATCH(E10,Lists!$A$2:$A$86,0)),"?")) | I10: =IF(OR(C10="",E10=""),"",IF(H10="Yes",IFERROR(INDEX(Employees!$E$4:$E$43,MATCH(C10,Employees!$B$4:$B$43,0)),0),0)) | J10: =IF(G10="","",IF(H10="Yes",G10*I10,0)) | K10: =IF(OR(C10="",G10=""),"",G10*IFERROR(INDEX(Employees!$F$4:$F$43,MATCH(C10,Employees!$B$4:$B$43,0)),0))
B11: =IF(A11="","",A11+7-WEEKDAY(A11,1)+1) | H11: =IF(E11="","",IFERROR(INDEX(Lists!$C$2:$C$86,MATCH(E11,Lists!$A$2:$A$86,0)),"?")) | I11: =IF(OR(C11="",E11=""),"",IF(H11="Yes",IFERROR(INDEX(Employees!$E$4:$E$43,MATCH(C11,Employees!$B$4:$B$43,0)),0),0)) | J11: =IF(G11="","",IF(H11="Yes",G11*I11,0)) | K11: =IF(OR(C11="",G11=""),"",G11*IFERROR(INDEX(Employees!$F$4:$F$43,MATCH(C11,Employees!$B$4:$B$43,0)),0))
B12: =IF(A12="","",A12+7-WEEKDAY(A12,1)+1) | H12: =IF(E12="","",IFERROR(INDEX(Lists!$C$2:$C$86,MATCH(E12,Lists!$A$2:$A$86,0)),"?")) | I12: =IF(OR(C12="",E12=""),"",IF(H12="Yes",IFERROR(INDEX(Employees!$E$4:$E$43,MATCH(C12,Employees!$B$4:$B$43,0)),0),0)) | J12: =IF(G12="","",IF(H12="Yes",G12*I12,0)) | K12: =IF(OR(C12="",G12=""),"",G12*IFERROR(INDEX(Employees!$F$4:$F$43,MATCH(C12,Employees!$B$4:$B$43,0)),0))
B13: =IF(A13="","",A13+7-WEEKDAY(A13,1)+1) | H13: =IF(E13="","",IFERROR(INDEX(Lists!$C$2:$C$86,MATCH(E13,Lists!$A$2:$A$86,0)),"?")) | I13: =IF(OR(C13="",E13=""),"",IF(H13="Yes",IFERROR(INDEX(Employees!$E$4:$E$43,MATCH(C13,Employees!$B$4:$B$43,0)),0),0)) | J13: =IF(G13="","",IF(H13="Yes",G13*I13,0)) | K13: =IF(OR(C13="",G13=""),"",G13*IFERROR(INDEX(Employees!$F$4:$F$43,MATCH(C13,Employees!$B$4:$B$43,0)),0))
B14: =IF(A14="","",A14+7-WEEKDAY(A14,1)+1) | H14: =IF(E14="","",IFERROR(INDEX(Lists!$C$2:$C$86,MATCH(E14,Lists!$A$2:$A$86,0)),"?")) | I14: =IF(OR(C14="",E14=""),"",IF(H14="Yes",IFERROR(INDEX(Employees!$E$4:$E$43,MATCH(C14,Employees!$B$4:$B$43,0)),0),0)) | J14: =IF(G14="","",IF(H14="Yes",G14*I14,0)) | K14: =IF(OR(C14="",G14=""),"",G14*IFERROR(INDEX(Employees!$F$4:$F$43,MATCH(C14,Employees!$B$4:$B$43,0)),0))
B15: =IF(A15="","",A15+7-WEEKDAY(A15,1)+1) | H15: =IF(E15="","",IFERROR(INDEX(Lists!$C$2:$C$86,MATCH(E15,Lists!$A$2:$A$86,0)),"?")) | I15: =IF(OR(C15="",E15=""),"",IF(H15="Yes",IFERROR(INDEX(Employees!$E$4:$E$43,MATCH(C15,Employees!$B$4:$B$43,0)),0),0)) | J15: =IF(G15="","",IF(H15="Yes",G15*I15,0)) | K15: =IF(OR(C15="",G15=""),"",G15*IFERROR(INDEX(Employees!$F$4:$F$43,MATCH(C15,Employees!$B$4:$B$43,0)),0))
B16: =IF(A16="","",A16+7-WEEKDAY(A16,1)+1) | H16: =IF(E16="","",IFERROR(INDEX(Lists!$C$2:$C$86,MATCH(E16,Lists!$A$2:$A$86,0)),"?")) | I16: =IF(OR(C16="",E16=""),"",IF(H16="Yes",IFERROR(INDEX(Employees!$E$4:$E$43,MATCH(C16,Employees!$B$4:$B$43,0)),0),0)) | J16: =IF(G16="","",IF(H16="Yes",G16*I16,0)) | K16: =IF(OR(C16="",G16=""),"",G16*IFERROR(INDEX(Employees!$F$4:$F$43,MATCH(C16,Employees!$B$4:$B$43,0)),0))
... B1003: =IF(A1003="","",A1003+7-WEEKDAY(A1003,1)+1) | H1003: =IF(E1003="","",IFERROR(INDEX(Lists!$C$2:$C$86,MATCH(E1003,Lists!$A$2:$A$86,0)),"?")) | I1003: =IF(OR(C1003="",E1003=""),"",IF(H1003="Yes",IFERROR(INDEX(Employees!$E$4:$E$43,MATCH(C1003,Employees!$B$4:$B$43,0)),0),0)) | J1003: =IF(G1003="","",IF(H1003="Yes",G1003*I1003,0)) | K1003: =IF(OR(C1003="",G1003=""),"",G1003*IFERROR(INDEX(Employees!$F$4:$F$43,MATCH(C1003,Employees!$B$4:$B$43,0)),0))

Sheet Projects
A1: Projects
A2: One row per active project/phase. Type drives billing behavior. Contract Fee is the total not-to-exceed or fixed fee.
A3: Project # | B3: Client | C3: Project Name | D3: Type | E3: Status | F3: Phase | G3: Contract Fee ($) | H3: Start Date | I3: Project Manager
A4: 25-014 | B4: Acme Powersports | C4: Handlebar Control Module Redesign | D4: Time & Materials | E4: Active | F4: Concept | G4: 85000 | I4: M. Hopkins
B65: ↑ Add one row per project (or per phase if you bill by phase). Row 4 is an example.

Sheet Employees
A1: Employees
A2: Fill the yellow cells. Bill Rate = default charge-out rate; Cost Rate = loaded hourly cost (salary+benefits)/2080.
A3: Emp ID | B3: Employee Name | C3: Role / Title | D3: Status | E3: Bill Rate ($/hr) | F3: Cost Rate ($/hr) | G3: Target Util %
A4: E001 | B4: Jane Designer | C4: Senior Industrial Designer | D4: Active | E4: 145 | F4: 68 | G4: 0.75
B45: ↑ Add one row per employee. Row 4 is a greyed example — overwrite it.

Sheet Indirect Codes
A1: Indirect Codes
A2: Non-billable time buckets (overhead). Everyone charges here when not on a billable project.
A3: Code | B3: Category | C3: Description
A4: OH-ADMIN | B4: Overhead | C4: General administration / operations
A5: OH-BD | B5: Business Dev | C5: Proposals, marketing, sales pursuits
A6: OH-PTO | B6: Paid Time Off | C6: Vacation
A7: OH-HOL | B7: Holiday | C7: Company holidays
A8: OH-SICK | B8: Sick | C8: Sick leave
A9: OH-TRAIN | B9: Training | C9: Professional development / training
A10: OH-MTG | B10: Overhead | C10: Internal meetings / company-wide
A11: OH-IT | B11: Overhead | C11: IT, facilities, equipment maintenance
A12: OH-RND | B12: R&D | C12: Internal / self-directed research
B30: ↑ Pre-filled with common buckets — edit to match your chart of overhead codes.

Sheet Project Summary
A1: Project Summary
A2: Auto-calculated from Time Entry and Invoices. WIP = billable value earned but not yet invoiced.
A3: Project # | B3: Client | C3: Project Name | D3: Contract Fee | E3: Hours | F3: Billable $ | G3: Cost $ | H3: Margin $ | I3: Invoiced $ | J3: WIP (Unbilled) $ | K3: % Fee Used
A4: =IF(Projects!$C$4="","",Projects!$A$4) -> 25-014 | B4: =IF(Projects!$C$4="","",Projects!$B$4) -> Acme Powersports | C4: =IF(Projects!$C$4="","",Projects!$C$4) -> Handlebar Control Module Redesign | D4: =IF(Projects!$C$4="","",Projects!$G$4) -> 85000 | E4: =IF(Projects!$C$4="","",SUMIFS('Time Entry'!$G$4:$G$1003,'Time Entry'!$E$4:$E$1003,Projects!$C$4)) -> 6.5 | F4: =IF(Projects!$C$4="","",SUMIFS('Time Entry'!$J$4:$J$1003,'Time Entry'!$E$4:$E$1003,Projects!$C$4)) -> 942.5 | G4: =IF(Projects!$C$4="","",SUMIFS('Time Entry'!$K$4:$K$1003,'Time Entry'!$E$4:$E$1003,Projects!$C$4)) -> 442 | H4: =IF(Projects!$C$4="","",F4-G4) -> 500.5 | I4: =IF(Projects!$C$4="","",SUMIFS(Invoices!$G$4:$G$203,Invoices!$D$4:$D$203,Projects!$C$4)) -> 900 | J4: =IF(Projects!$C$4="","",F4-I4) -> 42.5 | K4: =IF(OR(Projects!$C$4="",Projects!$G$4=0,Projects!$G$4=""),"",F4/Projects!$G$4) -> 0.011088235
A5: =IF(Projects!$C$5="","",Projects!$A$5) | B5: =IF(Projects!$C$5="","",Projects!$B$5) | C5: =IF(Projects!$C$5="","",Projects!$C$5) | D5: =IF(Projects!$C$5="","",Projects!$G$5) | E5: =IF(Projects!$C$5="","",SUMIFS('Time Entry'!$G$4:$G$1003,'Time Entry'!$E$4:$E$1003,Projects!$C$5)) | F5: =IF(Projects!$C$5="","",SUMIFS('Time Entry'!$J$4:$J$1003,'Time Entry'!$E$4:$E$1003,Projects!$C$5)) | G5: =IF(Projects!$C$5="","",SUMIFS('Time Entry'!$K$4:$K$1003,'Time Entry'!$E$4:$E$1003,Projects!$C$5)) | H5: =IF(Projects!$C$5="","",F5-G5) | I5: =IF(Projects!$C$5="","",SUMIFS(Invoices!$G$4:$G$203,Invoices!$D$4:$D$203,Projects!$C$5)) | J5: =IF(Projects!$C$5="","",F5-I5) | K5: =IF(OR(Projects!$C$5="",Projects!$G$5=0,Projects!$G$5=""),"",F5/Projects!$G$5)
A6: =IF(Projects!$C$6="","",Projects!$A$6) | B6: =IF(Projects!$C$6="","",Projects!$B$6) | C6: =IF(Projects!$C$6="","",Projects!$C$6) | D6: =IF(Projects!$C$6="","",Projects!$G$6) | E6: =IF(Projects!$C$6="","",SUMIFS('Time Entry'!$G$4:$G$1003,'Time Entry'!$E$4:$E$1003,Projects!$C$6)) | F6: =IF(Projects!$C$6="","",SUMIFS('Time Entry'!$J$4:$J$1003,'Time Entry'!$E$4:$E$1003,Projects!$C$6)) | G6: =IF(Projects!$C$6="","",SUMIFS('Time Entry'!$K$4:$K$1003,'Time Entry'!$E$4:$E$1003,Projects!$C$6)) | H6: =IF(Projects!$C$6="","",F6-G6) | I6: =IF(Projects!$C$6="","",SUMIFS(Invoices!$G$4:$G$203,Invoices!$D$4:$D$203,Projects!$C$6)) | J6: =IF(Projects!$C$6="","",F6-I6) | K6: =IF(OR(Projects!$C$6="",Projects!$G$6=0,Projects!$G$6=""),"",F6/Projects!$G$6)
A7: =IF(Projects!$C$7="","",Projects!$A$7) | B7: =IF(Projects!$C$7="","",Projects!$B$7) | C7: =IF(Projects!$C$7="","",Projects!$C$7) | D7: =IF(Projects!$C$7="","",Projects!$G$7) | E7: =IF(Projects!$C$7="","",SUMIFS('Time Entry'!$G$4:$G$1003,'Time Entry'!$E$4:$E$1003,Projects!$C$7)) | F7: =IF(Projects!$C$7="","",SUMIFS('Time Entry'!$J$4:$J$1003,'Time Entry'!$E$4:$E$1003,Projects!$C$7)) | G7: =IF(Projects!$C$7="","",SUMIFS('Time Entry'!$K$4:$K$1003,'Time Entry'!$E$4:$E$1003,Projects!$C$7)) | H7: =IF(Projects!$C$7="","",F7-G7) | I7: =IF(Projects!$C$7="","",SUMIFS(Invoices!$G$4:$G$203,Invoices!$D$4:$D$203,Projects!$C$7)) | J7: =IF(Projects!$C$7="","",F7-I7) | K7: =IF(OR(Projects!$C$7="",Projects!$G$7=0,Projects!$G$7=""),"",F7/Projects!$G$7)
A8: =IF(Projects!$C$8="","",Projects!$A$8) | B8: =IF(Projects!$C$8="","",Projects!$B$8) | C8: =IF(Projects!$C$8="","",Projects!$C$8) | D8: =IF(Projects!$C$8="","",Projects!$G$8) | E8: =IF(Projects!$C$8="","",SUMIFS('Time Entry'!$G$4:$G$1003,'Time Entry'!$E$4:$E$1003,Projects!$C$8)) | F8: =IF(Projects!$C$8="","",SUMIFS('Time Entry'!$J$4:$J$1003,'Time Entry'!$E$4:$E$1003,Projects!$C$8)) | G8: =IF(Projects!$C$8="","",SUMIFS('Time Entry'!$K$4:$K$1003,'Time Entry'!$E$4:$E$1003,Projects!$C$8)) | H8: =IF(Projects!$C$8="","",F8-G8) | I8: =IF(Projects!$C$8="","",SUMIFS(Invoices!$G$4:$G$203,Invoices!$D$4:$D$203,Projects!$C$8)) | J8: =IF(Projects!$C$8="","",F8-I8) | K8: =IF(OR(Projects!$C$8="",Projects!$G$8=0,Projects!$G$8=""),"",F8/Projects!$G$8)
A9: =IF(Projects!$C$9="","",Projects!$A$9) | B9: =IF(Projects!$C$9="","",Projects!$B$9) | C9: =IF(Projects!$C$9="","",Projects!$C$9) | D9: =IF(Projects!$C$9="","",Projects!$G$9) | E9: =IF(Projects!$C$9="","",SUMIFS('Time Entry'!$G$4:$G$1003,'Time Entry'!$E$4:$E$1003,Projects!$C$9)) | F9: =IF(Projects!$C$9="","",SUMIFS('Time Entry'!$J$4:$J$1003,'Time Entry'!$E$4:$E$1003,Projects!$C$9)) | G9: =IF(Projects!$C$9="","",SUMIFS('Time Entry'!$K$4:$K$1003,'Time Entry'!$E$4:$E$1003,Projects!$C$9)) | H9: =IF(Projects!$C$9="","",F9-G9) | I9: =IF(Projects!$C$9="","",SUMIFS(Invoices!$G$4:$G$203,Invoices!$D$4:$D$203,Projects!$C$9)) | J9: =IF(Projects!$C$9="","",F9-I9) | K9: =IF(OR(Projects!$C$9="",Projects!$G$9=0,Projects!$G$9=""),"",F9/Projects!$G$9)
A10: =IF(Projects!$C$10="","",Projects!$A$10) | B10: =IF(Projects!$C$10="","",Projects!$B$10) | C10: =IF(Projects!$C$10="","",Projects!$C$10) | D10: =IF(Projects!$C$10="","",Projects!$G$10) | E10: =IF(Projects!$C$10="","",SUMIFS('Time Entry'!$G$4:$G$1003,'Time Entry'!$E$4:$E$1003,Projects!$C$10)) | F10: =IF(Projects!$C$10="","",SUMIFS('Time Entry'!$J$4:$J$1003,'Time Entry'!$E$4:$E$1003,Projects!$C$10)) | G10: =IF(Projects!$C$10="","",SUMIFS('Time Entry'!$K$4:$K$1003,'Time Entry'!$E$4:$E$1003,Projects!$C$10)) | H10: =IF(Projects!$C$10="","",F10-G10) | I10: =IF(Projects!$C$10="","",SUMIFS(Invoices!$G$4:$G$203,Invoices!$D$4:$D$203,Projects!$C$10)) | J10: =IF(Projects!$C$10="","",F10-I10) | K10: =IF(OR(Projects!$C$10="",Projects!$G$10=0,Projects!$G$10=""),"",F10/Projects!$G$10)
A11: =IF(Projects!$C$11="","",Projects!$A$11) | B11: =IF(Projects!$C$11="","",Projects!$B$11) | C11: =IF(Projects!$C$11="","",Projects!$C$11) | D11: =IF(Projects!$C$11="","",Projects!$G$11) | E11: =IF(Projects!$C$11="","",SUMIFS('Time Entry'!$G$4:$G$1003,'Time Entry'!$E$4:$E$1003,Projects!$C$11)) | F11: =IF(Projects!$C$11="","",SUMIFS('Time Entry'!$J$4:$J$1003,'Time Entry'!$E$4:$E$1003,Projects!$C$11)) | G11: =IF(Projects!$C$11="","",SUMIFS('Time Entry'!$K$4:$K$1003,'Time Entry'!$E$4:$E$1003,Projects!$C$11)) | H11: =IF(Projects!$C$11="","",F11-G11) | I11: =IF(Projects!$C$11="","",SUMIFS(Invoices!$G$4:$G$203,Invoices!$D$4:$D$203,Projects!$C$11)) | J11: =IF(Projects!$C$11="","",F11-I11) | K11: =IF(OR(Projects!$C$11="",Projects!$G$11=0,Projects!$G$11=""),"",F11/Projects!$G$11)
A12: =IF(Projects!$C$12="","",Projects!$A$12) | B12: =IF(Projects!$C$12="","",Projects!$B$12) | C12: =IF(Projects!$C$12="","",Projects!$C$12) | D12: =IF(Projects!$C$12="","",Projects!$G$12) | E12: =IF(Projects!$C$12="","",SUMIFS('Time Entry'!$G$4:$G$1003,'Time Entry'!$E$4:$E$1003,Projects!$C$12)) | F12: =IF(Projects!$C$12="","",SUMIFS('Time Entry'!$J$4:$J$1003,'Time Entry'!$E$4:$E$1003,Projects!$C$12)) | G12: =IF(Projects!$C$12="","",SUMIFS('Time Entry'!$K$4:$K$1003,'Time Entry'!$E$4:$E$1003,Projects!$C$12)) | H12: =IF(Projects!$C$12="","",F12-G12) | I12: =IF(Projects!$C$12="","",SUMIFS(Invoices!$G$4:$G$203,Invoices!$D$4:$D$203,Projects!$C$12)) | J12: =IF(Projects!$C$12="","",F12-I12) | K12: =IF(OR(Projects!$C$12="",Projects!$G$12=0,Projects!$G$12=""),"",F12/Projects!$G$12)
A13: =IF(Projects!$C$13="","",Projects!$A$13) | B13: =IF(Projects!$C$13="","",Projects!$B$13) | C13: =IF(Projects!$C$13="","",Projects!$C$13) | D13: =IF(Projects!$C$13="","",Projects!$G$13) | E13: =IF(Projects!$C$13="","",SUMIFS('Time Entry'!$G$4:$G$1003,'Time Entry'!$E$4:$E$1003,Projects!$C$13)) | F13: =IF(Projects!$C$13="","",SUMIFS('Time Entry'!$J$4:$J$1003,'Time Entry'!$E$4:$E$1003,Projects!$C$13)) | G13: =IF(Projects!$C$13="","",SUMIFS('Time Entry'!$K$4:$K$1003,'Time Entry'!$E$4:$E$1003,Projects!$C$13)) | H13: =IF(Projects!$C$13="","",F13-G13) | I13: =IF(Projects!$C$13="","",SUMIFS(Invoices!$G$4:$G$203,Invoices!$D$4:$D$203,Projects!$C$13)) | J13: =IF(Projects!$C$13="","",F13-I13) | K13: =IF(OR(Projects!$C$13="",Projects!$G$13=0,Projects!$G$13=""),"",F13/Projects!$G$13)
A14: =IF(Projects!$C$14="","",Projects!$A$14) | B14: =IF(Projects!$C$14="","",Projects!$B$14) | C14: =IF(Projects!$C$14="","",Projects!$C$14) | D14: =IF(Projects!$C$14="","",Projects!$G$14) | E14: =IF(Projects!$C$14="","",SUMIFS('Time Entry'!$G$4:$G$1003,'Time Entry'!$E$4:$E$1003,Projects!$C$14)) | F14: =IF(Projects!$C$14="","",SUMIFS('Time Entry'!$J$4:$J$1003,'Time Entry'!$E$4:$E$1003,Projects!$C$14)) | G14: =IF(Projects!$C$14="","",SUMIFS('Time Entry'!$K$4:$K$1003,'Time Entry'!$E$4:$E$1003,Projects!$C$14)) | H14: =IF(Projects!$C$14="","",F14-G14) | I14: =IF(Projects!$C$14="","",SUMIFS(Invoices!$G$4:$G$203,Invoices!$D$4:$D$203,Projects!$C$14)) | J14: =IF(Projects!$C$14="","",F14-I14) | K14: =IF(OR(Projects!$C$14="",Projects!$G$14=0,Projects!$G$14=""),"",F14/Projects!$G$14)
A15: =IF(Projects!$C$15="","",Projects!$A$15) | B15: =IF(Projects!$C$15="","",Projects!$B$15) | C15: =IF(Projects!$C$15="","",Projects!$C$15) | D15: =IF(Projects!$C$15="","",Projects!$G$15) | E15: =IF(Projects!$C$15="","",SUMIFS('Time Entry'!$G$4:$G$1003,'Time Entry'!$E$4:$E$1003,Projects!$C$15)) | F15: =IF(Projects!$C$15="","",SUMIFS('Time Entry'!$J$4:$J$1003,'Time Entry'!$E$4:$E$1003,Projects!$C$15)) | G15: =IF(Projects!$C$15="","",SUMIFS('Time Entry'!$K$4:$K$1003,'Time Entry'!$E$4:$E$1003,Projects!$C$15)) | H15: =IF(Projects!$C$15="","",F15-G15) | I15: =IF(Projects!$C$15="","",SUMIFS(Invoices!$G$4:$G$203,Invoices!$D$4:$D$203,Projects!$C$15)) | J15: =IF(Projects!$C$15="","",F15-I15) | K15: =IF(OR(Projects!$C$15="",Projects!$G$15=0,Projects!$G$15=""),"",F15/Projects!$G$15)
A16: =IF(Projects!$C$16="","",Projects!$A$16) | B16: =IF(Projects!$C$16="","",Projects!$B$16) | C16: =IF(Projects!$C$16="","",Projects!$C$16) | D16: =IF(Projects!$C$16="","",Projects!$G$16) | E16: =IF(Projects!$C$16="","",SUMIFS('Time Entry'!$G$4:$G$1003,'Time Entry'!$E$4:$E$1003,Projects!$C$16)) | F16: =IF(Projects!$C$16="","",SUMIFS('Time Entry'!$J$4:$J$1003,'Time Entry'!$E$4:$E$1003,Projects!$C$16)) | G16: =IF(Projects!$C$16="","",SUMIFS('Time Entry'!$K$4:$K$1003,'Time Entry'!$E$4:$E$1003,Projects!$C$16)) | H16: =IF(Projects!$C$16="","",F16-G16) | I16: =IF(Projects!$C$16="","",SUMIFS(Invoices!$G$4:$G$203,Invoices!$D$4:$D$203,Projects!$C$16)) | J16: =IF(Projects!$C$16="","",F16-I16) | K16: =IF(OR(Projects!$C$16="",Projects!$G$16=0,Projects!$G$16=""),"",F16/Projects!$G$16)
A17: =IF(Projects!$C$17="","",Projects!$A$17) | B17: =IF(Projects!$C$17="","",Projects!$B$17) | C17: =IF(Projects!$C$17="","",Projects!$C$17) | D17: =IF(Projects!$C$17="","",Projects!$G$17) | E17: =IF(Projects!$C$17="","",SUMIFS('Time Entry'!$G$4:$G$1003,'Time Entry'!$E$4:$E$1003,Projects!$C$17)) | F17: =IF(Projects!$C$17="","",SUMIFS('Time Entry'!$J$4:$J$1003,'Time Entry'!$E$4:$E$1003,Projects!$C$17)) | G17: =IF(Projects!$C$17="","",SUMIFS('Time Entry'!$K$4:$K$1003,'Time Entry'!$E$4:$E$1003,Projects!$C$17)) | H17: =IF(Projects!$C$17="","",F17-G17) | I17: =IF(Projects!$C$17="","",SUMIFS(Invoices!$G$4:$G$203,Invoices!$D$4:$D$203,Projects!$C$17)) | J17: =IF(Projects!$C$17="","",F17-I17) | K17: =IF(OR(Projects!$C$17="",Projects!$G$17=0,Projects!$G$17=""),"",F17/Projects!$G$17)
A18: =IF(Projects!$C$18="","",Projects!$A$18) | B18: =IF(Projects!$C$18="","",Projects!$B$18) | C18: =IF(Projects!$C$18="","",Projects!$C$18) | D18: =IF(Projects!$C$18="","",Projects!$G$18) | E18: =IF(Projects!$C$18="","",SUMIFS('Time Entry'!$G$4:$G$1003,'Time Entry'!$E$4:$E$1003,Projects!$C$18)) | F18: =IF(Projects!$C$18="","",SUMIFS('Time Entry'!$J$4:$J$1003,'Time Entry'!$E$4:$E$1003,Projects!$C$18)) | G18: =IF(Projects!$C$18="","",SUMIFS('Time Entry'!$K$4:$K$1003,'Time Entry'!$E$4:$E$1003,Projects!$C$18)) | H18: =IF(Projects!$C$18="","",F18-G18) | I18: =IF(Projects!$C$18="","",SUMIFS(Invoices!$G$4:$G$203,Invoices!$D$4:$D$203,Projects!$C$18)) | J18: =IF(Projects!$C$18="","",F18-I18) | K18: =IF(OR(Projects!$C$18="",Projects!$G$18=0,Projects!$G$18=""),"",F18/Projects!$G$18)
A19: =IF(Projects!$C$19="","",Projects!$A$19) | B19: =IF(Projects!$C$19="","",Projects!$B$19) | C19: =IF(Projects!$C$19="","",Projects!$C$19) | D19: =IF(Projects!$C$19="","",Projects!$G$19) | E19: =IF(Projects!$C$19="","",SUMIFS('Time Entry'!$G$4:$G$1003,'Time Entry'!$E$4:$E$1003,Projects!$C$19)) | F19: =IF(Projects!$C$19="","",SUMIFS('Time Entry'!$J$4:$J$1003,'Time Entry'!$E$4:$E$1003,Projects!$C$19)) | G19: =IF(Projects!$C$19="","",SUMIFS('Time Entry'!$K$4:$K$1003,'Time Entry'!$E$4:$E$1003,Projects!$C$19)) | H19: =IF(Projects!$C$19="","",F19-G19) | I19: =IF(Projects!$C$19="","",SUMIFS(Invoices!$G$4:$G$203,Invoices!$D$4:$D$203,Projects!$C$19)) | J19: =IF(Projects!$C$19="","",F19-I19) | K19: =IF(OR(Projects!$C$19="",Projects!$G$19=0,Projects!$G$19=""),"",F19/Projects!$G$19)
A20: =IF(Projects!$C$20="","",Projects!$A$20) | B20: =IF(Projects!$C$20="","",Projects!$B$20) | C20: =IF(Projects!$C$20="","",Projects!$C$20) | D20: =IF(Projects!$C$20="","",Projects!$G$20) | E20: =IF(Projects!$C$20="","",SUMIFS('Time Entry'!$G$4:$G$1003,'Time Entry'!$E$4:$E$1003,Projects!$C$20)) | F20: =IF(Projects!$C$20="","",SUMIFS('Time Entry'!$J$4:$J$1003,'Time Entry'!$E$4:$E$1003,Projects!$C$20)) | G20: =IF(Projects!$C$20="","",SUMIFS('Time Entry'!$K$4:$K$1003,'Time Entry'!$E$4:$E$1003,Projects!$C$20)) | H20: =IF(Projects!$C$20="","",F20-G20) | I20: =IF(Projects!$C$20="","",SUMIFS(Invoices!$G$4:$G$203,Invoices!$D$4:$D$203,Projects!$C$20)) | J20: =IF(Projects!$C$20="","",F20-I20) | K20: =IF(OR(Projects!$C$20="",Projects!$G$20=0,Projects!$G$20=""),"",F20/Projects!$G$20)
A21: =IF(Projects!$C$21="","",Projects!$A$21) | B21: =IF(Projects!$C$21="","",Projects!$B$21) | C21: =IF(Projects!$C$21="","",Projects!$C$21) | D21: =IF(Projects!$C$21="","",Projects!$G$21) | E21: =IF(Projects!$C$21="","",SUMIFS('Time Entry'!$G$4:$G$1003,'Time Entry'!$E$4:$E$1003,Projects!$C$21)) | F21: =IF(Projects!$C$21="","",SUMIFS('Time Entry'!$J$4:$J$1003,'Time Entry'!$E$4:$E$1003,Projects!$C$21)) | G21: =IF(Projects!$C$21="","",SUMIFS('Time Entry'!$K$4:$K$1003,'Time Entry'!$E$4:$E$1003,Projects!$C$21)) | H21: =IF(Projects!$C$21="","",F21-G21) | I21: =IF(Projects!$C$21="","",SUMIFS(Invoices!$G$4:$G$203,Invoices!$D$4:$D$203,Projects!$C$21)) | J21: =IF(Projects!$C$21="","",F21-I21) | K21: =IF(OR(Projects!$C$21="",Projects!$G$21=0,Projects!$G$21=""),"",F21/Projects!$G$21)
A22: =IF(Projects!$C$22="","",Projects!$A$22) | B22: =IF(Projects!$C$22="","",Projects!$B$22) | C22: =IF(Projects!$C$22="","",Projects!$C$22) | D22: =IF(Projects!$C$22="","",Projects!$G$22) | E22: =IF(Projects!$C$22="","",SUMIFS('Time Entry'!$G$4:$G$1003,'Time Entry'!$E$4:$E$1003,Projects!$C$22)) | F22: =IF(Projects!$C$22="","",SUMIFS('Time Entry'!$J$4:$J$1003,'Time Entry'!$E$4:$E$1003,Projects!$C$22)) | G22: =IF(Projects!$C$22="","",SUMIFS('Time Entry'!$K$4:$K$1003,'Time Entry'!$E$4:$E$1003,Projects!$C$22)) | H22: =IF(Projects!$C$22="","",F22-G22) | I22: =IF(Projects!$C$22="","",SUMIFS(Invoices!$G$4:$G$203,Invoices!$D$4:$D$203,Projects!$C$22)) | J22: =IF(Projects!$C$22="","",F22-I22) | K22: =IF(OR(Projects!$C$22="",Projects!$G$22=0,Projects!$G$22=""),"",F22/Projects!$G$22)
A23: =IF(Projects!$C$23="","",Projects!$A$23) | B23: =IF(Projects!$C$23="","",Projects!$B$23) | C23: =IF(Projects!$C$23="","",Projects!$C$23) | D23: =IF(Projects!$C$23="","",Projects!$G$23) | E23: =IF(Projects!$C$23="","",SUMIFS('Time Entry'!$G$4:$G$1003,'Time Entry'!$E$4:$E$1003,Projects!$C$23)) | F23: =IF(Projects!$C$23="","",SUMIFS('Time Entry'!$J$4:$J$1003,'Time Entry'!$E$4:$E$1003,Projects!$C$23)) | G23: =IF(Projects!$C$23="","",SUMIFS('Time Entry'!$K$4:$K$1003,'Time Entry'!$E$4:$E$1003,Projects!$C$23)) | H23: =IF(Projects!$C$23="","",F23-G23) | I23: =IF(Projects!$C$23="","",SUMIFS(Invoices!$G$4:$G$203,Invoices!$D$4:$D$203,Projects!$C$23)) | J23: =IF(Projects!$C$23="","",F23-I23) | K23: =IF(OR(Projects!$C$23="",Projects!$G$23=0,Projects!$G$23=""),"",F23/Projects!$G$23)
A24: =IF(Projects!$C$24="","",Projects!$A$24) | B24: =IF(Projects!$C$24="","",Projects!$B$24) | C24: =IF(Projects!$C$24="","",Projects!$C$24) | D24: =IF(Projects!$C$24="","",Projects!$G$24) | E24: =IF(Projects!$C$24="","",SUMIFS('Time Entry'!$G$4:$G$1003,'Time Entry'!$E$4:$E$1003,Projects!$C$24)) | F24: =IF(Projects!$C$24="","",SUMIFS('Time Entry'!$J$4:$J$1003,'Time Entry'!$E$4:$E$1003,Projects!$C$24)) | G24: =IF(Projects!$C$24="","",SUMIFS('Time Entry'!$K$4:$K$1003,'Time Entry'!$E$4:$E$1003,Projects!$C$24)) | H24: =IF(Projects!$C$24="","",F24-G24) | I24: =IF(Projects!$C$24="","",SUMIFS(Invoices!$G$4:$G$203,Invoices!$D$4:$D$203,Projects!$C$24)) | J24: =IF(Projects!$C$24="","",F24-I24) | K24: =IF(OR(Projects!$C$24="",Projects!$G$24=0,Projects!$G$24=""),"",F24/Projects!$G$24)
A25: =IF(Projects!$C$25="","",Projects!$A$25) | B25: =IF(Projects!$C$25="","",Projects!$B$25) | C25: =IF(Projects!$C$25="","",Projects!$C$25) | D25: =IF(Projects!$C$25="","",Projects!$G$25) | E25: =IF(Projects!$C$25="","",SUMIFS('Time Entry'!$G$4:$G$1003,'Time Entry'!$E$4:$E$1003,Projects!$C$25)) | F25: =IF(Projects!$C$25="","",SUMIFS('Time Entry'!$J$4:$J$1003,'Time Entry'!$E$4:$E$1003,Projects!$C$25)) | G25: =IF(Projects!$C$25="","",SUMIFS('Time Entry'!$K$4:$K$1003,'Time Entry'!$E$4:$E$1003,Projects!$C$25)) | H25: =IF(Projects!$C$25="","",F25-G25) | I25: =IF(Projects!$C$25="","",SUMIFS(Invoices!$G$4:$G$203,Invoices!$D$4:$D$203,Projects!$C$25)) | J25: =IF(Projects!$C$25="","",F25-I25) | K25: =IF(OR(Projects!$C$25="",Projects!$G$25=0,Projects!$G$25=""),"",F25/Projects!$G$25)
A26: =IF(Projects!$C$26="","",Projects!$A$26) | B26: =IF(Projects!$C$26="","",Projects!$B$26) | C26: =IF(Projects!$C$26="","",Projects!$C$26) | D26: =IF(Projects!$C$26="","",Projects!$G$26) | E26: =IF(Projects!$C$26="","",SUMIFS('Time Entry'!$G$4:$G$1003,'Time Entry'!$E$4:$E$1003,Projects!$C$26)) | F26: =IF(Projects!$C$26="","",SUMIFS('Time Entry'!$J$4:$J$1003,'Time Entry'!$E$4:$E$1003,Projects!$C$26)) | G26: =IF(Projects!$C$26="","",SUMIFS('Time Entry'!$K$4:$K$1003,'Time Entry'!$E$4:$E$1003,Projects!$C$26)) | H26: =IF(Projects!$C$26="","",F26-G26) | I26: =IF(Projects!$C$26="","",SUMIFS(Invoices!$G$4:$G$203,Invoices!$D$4:$D$203,Projects!$C$26)) | J26: =IF(Projects!$C$26="","",F26-I26) | K26: =IF(OR(Projects!$C$26="",Projects!$G$26=0,Projects!$G$26=""),"",F26/Projects!$G$26)
A27: =IF(Projects!$C$27="","",Projects!$A$27) | B27: =IF(Projects!$C$27="","",Projects!$B$27) | C27: =IF(Projects!$C$27="","",Projects!$C$27) | D27: =IF(Projects!$C$27="","",Projects!$G$27) | E27: =IF(Projects!$C$27="","",SUMIFS('Time Entry'!$G$4:$G$1003,'Time Entry'!$E$4:$E$1003,Projects!$C$27)) | F27: =IF(Projects!$C$27="","",SUMIFS('Time Entry'!$J$4:$J$1003,'Time Entry'!$E$4:$E$1003,Projects!$C$27)) | G27: =IF(Projects!$C$27="","",SUMIFS('Time Entry'!$K$4:$K$1003,'Time Entry'!$E$4:$E$1003,Projects!$C$27)) | H27: =IF(Projects!$C$27="","",F27-G27) | I27: =IF(Projects!$C$27="","",SUMIFS(Invoices!$G$4:$G$203,Invoices!$D$4:$D$203,Projects!$C$27)) | J27: =IF(Projects!$C$27="","",F27-I27) | K27: =IF(OR(Projects!$C$27="",Projects!$G$27=0,Projects!$G$27=""),"",F27/Projects!$G$27)
A28: =IF(Projects!$C$28="","",Projects!$A$28) | B28: =IF(Projects!$C$28="","",Projects!$B$28) | C28: =IF(Projects!$C$28="","",Projects!$C$28) | D28: =IF(Projects!$C$28="","",Projects!$G$28) | E28: =IF(Projects!$C$28="","",SUMIFS('Time Entry'!$G$4:$G$1003,'Time Entry'!$E$4:$E$1003,Projects!$C$28)) | F28: =IF(Projects!$C$28="","",SUMIFS('Time Entry'!$J$4:$J$1003,'Time Entry'!$E$4:$E$1003,Projects!$C$28)) | G28: =IF(Projects!$C$28="","",SUMIFS('Time Entry'!$K$4:$K$1003,'Time Entry'!$E$4:$E$1003,Projects!$C$28)) | H28: =IF(Projects!$C$28="","",F28-G28) | I28: =IF(Projects!$C$28="","",SUMIFS(Invoices!$G$4:$G$203,Invoices!$D$4:$D$203,Projects!$C$28)) | J28: =IF(Projects!$C$28="","",F28-I28) | K28: =IF(OR(Projects!$C$28="",Projects!$G$28=0,Projects!$G$28=""),"",F28/Projects!$G$28)
A29: =IF(Projects!$C$29="","",Projects!$A$29) | B29: =IF(Projects!$C$29="","",Projects!$B$29) | C29: =IF(Projects!$C$29="","",Projects!$C$29) | D29: =IF(Projects!$C$29="","",Projects!$G$29) | E29: =IF(Projects!$C$29="","",SUMIFS('Time Entry'!$G$4:$G$1003,'Time Entry'!$E$4:$E$1003,Projects!$C$29)) | F29: =IF(Projects!$C$29="","",SUMIFS('Time Entry'!$J$4:$J$1003,'Time Entry'!$E$4:$E$1003,Projects!$C$29)) | G29: =IF(Projects!$C$29="","",SUMIFS('Time Entry'!$K$4:$K$1003,'Time Entry'!$E$4:$E$1003,Projects!$C$29)) | H29: =IF(Projects!$C$29="","",F29-G29) | I29: =IF(Projects!$C$29="","",SUMIFS(Invoices!$G$4:$G$203,Invoices!$D$4:$D$203,Projects!$C$29)) | J29: =IF(Projects!$C$29="","",F29-I29) | K29: =IF(OR(Projects!$C$29="",Projects!$G$29=0,Projects!$G$29=""),"",F29/Projects!$G$29)
A30: =IF(Projects!$C$30="","",Projects!$A$30) | B30: =IF(Projects!$C$30="","",Projects!$B$30) | C30: =IF(Projects!$C$30="","",Projects!$C$30) | D30: =IF(Projects!$C$30="","",Projects!$G$30) | E30: =IF(Projects!$C$30="","",SUMIFS('Time Entry'!$G$4:$G$1003,'Time Entry'!$E$4:$E$1003,Projects!$C$30)) | F30: =IF(Projects!$C$30="","",SUMIFS('Time Entry'!$J$4:$J$1003,'Time Entry'!$E$4:$E$1003,Projects!$C$30)) | G30: =IF(Projects!$C$30="","",SUMIFS('Time Entry'!$K$4:$K$1003,'Time Entry'!$E$4:$E$1003,Projects!$C$30)) | H30: =IF(Projects!$C$30="","",F30-G30) | I30: =IF(Projects!$C$30="","",SUMIFS(Invoices!$G$4:$G$203,Invoices!$D$4:$D$203,Projects!$C$30)) | J30: =IF(Projects!$C$30="","",F30-I30) | K30: =IF(OR(Projects!$C$30="",Projects!$G$30=0,Projects!$G$30=""),"",F30/Projects!$G$30)
A31: =IF(Projects!$C$31="","",Projects!$A$31) | B31: =IF(Projects!$C$31="","",Projects!$B$31) | C31: =IF(Projects!$C$31="","",Projects!$C$31) | D31: =IF(Projects!$C$31="","",Projects!$G$31) | E31: =IF(Projects!$C$31="","",SUMIFS('Time Entry'!$G$4:$G$1003,'Time Entry'!$E$4:$E$1003,Projects!$C$31)) | F31: =IF(Projects!$C$31="","",SUMIFS('Time Entry'!$J$4:$J$1003,'Time Entry'!$E$4:$E$1003,Projects!$C$31)) | G31: =IF(Projects!$C$31="","",SUMIFS('Time Entry'!$K$4:$K$1003,'Time Entry'!$E$4:$E$1003,Projects!$C$31)) | H31: =IF(Projects!$C$31="","",F31-G31) | I31: =IF(Projects!$C$31="","",SUMIFS(Invoices!$G$4:$G$203,Invoices!$D$4:$D$203,Projects!$C$31)) | J31: =IF(Projects!$C$31="","",F31-I31) | K31: =IF(OR(Projects!$C$31="",Projects!$G$31=0,Projects!$G$31=""),"",F31/Projects!$G$31)
A32: =IF(Projects!$C$32="","",Projects!$A$32) | B32: =IF(Projects!$C$32="","",Projects!$B$32) | C32: =IF(Projects!$C$32="","",Projects!$C$32) | D32: =IF(Projects!$C$32="","",Projects!$G$32) | E32: =IF(Projects!$C$32="","",SUMIFS('Time Entry'!$G$4:$G$1003,'Time Entry'!$E$4:$E$1003,Projects!$C$32)) | F32: =IF(Projects!$C$32="","",SUMIFS('Time Entry'!$J$4:$J$1003,'Time Entry'!$E$4:$E$1003,Projects!$C$32)) | G32: =IF(Projects!$C$32="","",SUMIFS('Time Entry'!$K$4:$K$1003,'Time Entry'!$E$4:$E$1003,Projects!$C$32)) | H32: =IF(Projects!$C$32="","",F32-G32) | I32: =IF(Projects!$C$32="","",SUMIFS(Invoices!$G$4:$G$203,Invoices!$D$4:$D$203,Projects!$C$32)) | J32: =IF(Projects!$C$32="","",F32-I32) | K32: =IF(OR(Projects!$C$32="",Projects!$G$32=0,Projects!$G$32=""),"",F32/Projects!$G$32)
A33: =IF(Projects!$C$33="","",Projects!$A$33) | B33: =IF(Projects!$C$33="","",Projects!$B$33) | C33: =IF(Projects!$C$33="","",Projects!$C$33) | D33: =IF(Projects!$C$33="","",Projects!$G$33) | E33: =IF(Projects!$C$33="","",SUMIFS('Time Entry'!$G$4:$G$1003,'Time Entry'!$E$4:$E$1003,Projects!$C$33)) | F33: =IF(Projects!$C$33="","",SUMIFS('Time Entry'!$J$4:$J$1003,'Time Entry'!$E$4:$E$1003,Projects!$C$33)) | G33: =IF(Projects!$C$33="","",SUMIFS('Time Entry'!$K$4:$K$1003,'Time Entry'!$E$4:$E$1003,Projects!$C$33)) | H33: =IF(Projects!$C$33="","",F33-G33) | I33: =IF(Projects!$C$33="","",SUMIFS(Invoices!$G$4:$G$203,Invoices!$D$4:$D$203,Projects!$C$33)) | J33: =IF(Projects!$C$33="","",F33-I33) | K33: =IF(OR(Projects!$C$33="",Projects!$G$33=0,Projects!$G$33=""),"",F33/Projects!$G$33)
A34: =IF(Projects!$C$34="","",Projects!$A$34) | B34: =IF(Projects!$C$34="","",Projects!$B$34) | C34: =IF(Projects!$C$34="","",Projects!$C$34) | D34: =IF(Projects!$C$34="","",Projects!$G$34) | E34: =IF(Projects!$C$34="","",SUMIFS('Time Entry'!$G$4:$G$1003,'Time Entry'!$E$4:$E$1003,Projects!$C$34)) | F34: =IF(Projects!$C$34="","",SUMIFS('Time Entry'!$J$4:$J$1003,'Time Entry'!$E$4:$E$1003,Projects!$C$34)) | G34: =IF(Projects!$C$34="","",SUMIFS('Time Entry'!$K$4:$K$1003,'Time Entry'!$E$4:$E$1003,Projects!$C$34)) | H34: =IF(Projects!$C$34="","",F34-G34) | I34: =IF(Projects!$C$34="","",SUMIFS(Invoices!$G$4:$G$203,Invoices!$D$4:$D$203,Projects!$C$34)) | J34: =IF(Projects!$C$34="","",F34-I34) | K34: =IF(OR(Projects!$C$34="",Projects!$G$34=0,Projects!$G$34=""),"",F34/Projects!$G$34)
A35: =IF(Projects!$C$35="","",Projects!$A$35) | B35: =IF(Projects!$C$35="","",Projects!$B$35) | C35: =IF(Projects!$C$35="","",Projects!$C$35) | D35: =IF(Projects!$C$35="","",Projects!$G$35) | E35: =IF(Projects!$C$35="","",SUMIFS('Time Entry'!$G$4:$G$1003,'Time Entry'!$E$4:$E$1003,Projects!$C$35)) | F35: =IF(Projects!$C$35="","",SUMIFS('Time Entry'!$J$4:$J$1003,'Time Entry'!$E$4:$E$1003,Projects!$C$35)) | G35: =IF(Projects!$C$35="","",SUMIFS('Time Entry'!$K$4:$K$1003,'Time Entry'!$E$4:$E$1003,Projects!$C$35)) | H35: =IF(Projects!$C$35="","",F35-G35) | I35: =IF(Projects!$C$35="","",SUMIFS(Invoices!$G$4:$G$203,Invoices!$D$4:$D$203,Projects!$C$35)) | J35: =IF(Projects!$C$35="","",F35-I35) | K35: =IF(OR(Projects!$C$35="",Projects!$G$35=0,Projects!$G$35=""),"",F35/Projects!$G$35)
A36: =IF(Projects!$C$36="","",Projects!$A$36) | B36: =IF(Projects!$C$36="","",Projects!$B$36) | C36: =IF(Projects!$C$36="","",Projects!$C$36) | D36: =IF(Projects!$C$36="","",Projects!$G$36) | E36: =IF(Projects!$C$36="","",SUMIFS('Time Entry'!$G$4:$G$1003,'Time Entry'!$E$4:$E$1003,Projects!$C$36)) | F36: =IF(Projects!$C$36="","",SUMIFS('Time Entry'!$J$4:$J$1003,'Time Entry'!$E$4:$E$1003,Projects!$C$36)) | G36: =IF(Projects!$C$36="","",SUMIFS('Time Entry'!$K$4:$K$1003,'Time Entry'!$E$4:$E$1003,Projects!$C$36)) | H36: =IF(Projects!$C$36="","",F36-G36) | I36: =IF(Projects!$C$36="","",SUMIFS(Invoices!$G$4:$G$203,Invoices!$D$4:$D$203,Projects!$C$36)) | J36: =IF(Projects!$C$36="","",F36-I36) | K36: =IF(OR(Projects!$C$36="",Projects!$G$36=0,Projects!$G$36=""),"",F36/Projects!$G$36)
A37: =IF(Projects!$C$37="","",Projects!$A$37) | B37: =IF(Projects!$C$37="","",Projects!$B$37) | C37: =IF(Projects!$C$37="","",Projects!$C$37) | D37: =IF(Projects!$C$37="","",Projects!$G$37) | E37: =IF(Projects!$C$37="","",SUMIFS('Time Entry'!$G$4:$G$1003,'Time Entry'!$E$4:$E$1003,Projects!$C$37)) | F37: =IF(Projects!$C$37="","",SUMIFS('Time Entry'!$J$4:$J$1003,'Time Entry'!$E$4:$E$1003,Projects!$C$37)) | G37: =IF(Projects!$C$37="","",SUMIFS('Time Entry'!$K$4:$K$1003,'Time Entry'!$E$4:$E$1003,Projects!$C$37)) | H37: =IF(Projects!$C$37="","",F37-G37) | I37: =IF(Projects!$C$37="","",SUMIFS(Invoices!$G$4:$G$203,Invoices!$D$4:$D$203,Projects!$C$37)) | J37: =IF(Projects!$C$37="","",F37-I37) | K37: =IF(OR(Projects!$C$37="",Projects!$G$37=0,Projects!$G$37=""),"",F37/Projects!$G$37)
A38: =IF(Projects!$C$38="","",Projects!$A$38) | B38: =IF(Projects!$C$38="","",Projects!$B$38) | C38: =IF(Projects!$C$38="","",Projects!$C$38) | D38: =IF(Projects!$C$38="","",Projects!$G$38) | E38: =IF(Projects!$C$38="","",SUMIFS('Time Entry'!$G$4:$G$1003,'Time Entry'!$E$4:$E$1003,Projects!$C$38)) | F38: =IF(Projects!$C$38="","",SUMIFS('Time Entry'!$J$4:$J$1003,'Time Entry'!$E$4:$E$1003,Projects!$C$38)) | G38: =IF(Projects!$C$38="","",SUMIFS('Time Entry'!$K$4:$K$1003,'Time Entry'!$E$4:$E$1003,Projects!$C$38)) | H38: =IF(Projects!$C$38="","",F38-G38) | I38: =IF(Projects!$C$38="","",SUMIFS(Invoices!$G$4:$G$203,Invoices!$D$4:$D$203,Projects!$C$38)) | J38: =IF(Projects!$C$38="","",F38-I38) | K38: =IF(OR(Projects!$C$38="",Projects!$G$38=0,Projects!$G$38=""),"",F38/Projects!$G$38)
A39: =IF(Projects!$C$39="","",Projects!$A$39) | B39: =IF(Projects!$C$39="","",Projects!$B$39) | C39: =IF(Projects!$C$39="","",Projects!$C$39) | D39: =IF(Projects!$C$39="","",Projects!$G$39) | E39: =IF(Projects!$C$39="","",SUMIFS('Time Entry'!$G$4:$G$1003,'Time Entry'!$E$4:$E$1003,Projects!$C$39)) | F39: =IF(Projects!$C$39="","",SUMIFS('Time Entry'!$J$4:$J$1003,'Time Entry'!$E$4:$E$1003,Projects!$C$39)) | G39: =IF(Projects!$C$39="","",SUMIFS('Time Entry'!$K$4:$K$1003,'Time Entry'!$E$4:$E$1003,Projects!$C$39)) | H39: =IF(Projects!$C$39="","",F39-G39) | I39: =IF(Projects!$C$39="","",SUMIFS(Invoices!$G$4:$G$203,Invoices!$D$4:$D$203,Projects!$C$39)) | J39: =IF(Projects!$C$39="","",F39-I39) | K39: =IF(OR(Projects!$C$39="",Projects!$G$39=0,Projects!$G$39=""),"",F39/Projects!$G$39)
A40: =IF(Projects!$C$40="","",Projects!$A$40) | B40: =IF(Projects!$C$40="","",Projects!$B$40) | C40: =IF(Projects!$C$40="","",Projects!$C$40) | D40: =IF(Projects!$C$40="","",Projects!$G$40) | E40: =IF(Projects!$C$40="","",SUMIFS('Time Entry'!$G$4:$G$1003,'Time Entry'!$E$4:$E$1003,Projects!$C$40)) | F40: =IF(Projects!$C$40="","",SUMIFS('Time Entry'!$J$4:$J$1003,'Time Entry'!$E$4:$E$1003,Projects!$C$40)) | G40: =IF(Projects!$C$40="","",SUMIFS('Time Entry'!$K$4:$K$1003,'Time Entry'!$E$4:$E$1003,Projects!$C$40)) | H40: =IF(Projects!$C$40="","",F40-G40) | I40: =IF(Projects!$C$40="","",SUMIFS(Invoices!$G$4:$G$203,Invoices!$D$4:$D$203,Projects!$C$40)) | J40: =IF(Projects!$C$40="","",F40-I40) | K40: =IF(OR(Projects!$C$40="",Projects!$G$40=0,Projects!$G$40=""),"",F40/Projects!$G$40)
...

Sheet Utilization
A1: Utilization
A2: Billable vs total hours by person. Utilization = billable hours / total hours. Compare to each person's target.
A3: Employee | B3: Total Hours | C3: Billable Hours | D3: Indirect Hours | E3: Utilization % | F3: Target % | G3: Billable $
A4: =IF(Employees!$B$4="","",Employees!$B$4) -> Jane Designer | B4: =IF(Employees!$B$4="","",SUMIFS('Time Entry'!$G$4:$G$1003,'Time Entry'!$C$4:$C$1003,Employees!$B$4)) -> 6.5 | C4: =IF(Employees!$B$4="","",SUMIFS('Time Entry'!$G$4:$G$1003,'Time Entry'!$C$4:$C$1003,Employees!$B$4,'Time Entry'!$H$4:$H$1003,"Yes")) -> 6.5 | D4: =IF(Employees!$B$4="","",B4-C4) -> 0 | E4: =IF(OR(Employees!$B$4="",B4=0),"",C4/B4) -> 1 | F4: =IF(Employees!$B$4="","",Employees!$G$4) -> 0.75 | G4: =IF(Employees!$B$4="","",SUMIFS('Time Entry'!$J$4:$J$1003,'Time Entry'!$C$4:$C$1003,Employees!$B$4)) -> 942.5
A5: =IF(Employees!$B$5="","",Employees!$B$5) | B5: =IF(Employees!$B$5="","",SUMIFS('Time Entry'!$G$4:$G$1003,'Time Entry'!$C$4:$C$1003,Employees!$B$5)) | C5: =IF(Employees!$B$5="","",SUMIFS('Time Entry'!$G$4:$G$1003,'Time Entry'!$C$4:$C$1003,Employees!$B$5,'Time Entry'!$H$4:$H$1003,"Yes")) | D5: =IF(Employees!$B$5="","",B5-C5) | E5: =IF(OR(Employees!$B$5="",B5=0),"",C5/B5) | F5: =IF(Employees!$B$5="","",Employees!$G$5) | G5: =IF(Employees!$B$5="","",SUMIFS('Time Entry'!$J$4:$J$1003,'Time Entry'!$C$4:$C$1003,Employees!$B$5))
A6: =IF(Employees!$B$6="","",Employees!$B$6) | B6: =IF(Employees!$B$6="","",SUMIFS('Time Entry'!$G$4:$G$1003,'Time Entry'!$C$4:$C$1003,Employees!$B$6)) | C6: =IF(Employees!$B$6="","",SUMIFS('Time Entry'!$G$4:$G$1003,'Time Entry'!$C$4:$C$1003,Employees!$B$6,'Time Entry'!$H$4:$H$1003,"Yes")) | D6: =IF(Employees!$B$6="","",B6-C6) | E6: =IF(OR(Employees!$B$6="",B6=0),"",C6/B6) | F6: =IF(Employees!$B$6="","",Employees!$G$6) | G6: =IF(Employees!$B$6="","",SUMIFS('Time Entry'!$J$4:$J$1003,'Time Entry'!$C$4:$C$1003,Employees!$B$6))
A7: =IF(Employees!$B$7="","",Employees!$B$7) | B7: =IF(Employees!$B$7="","",SUMIFS('Time Entry'!$G$4:$G$1003,'Time Entry'!$C$4:$C$1003,Employees!$B$7)) | C7: =IF(Employees!$B$7="","",SUMIFS('Time Entry'!$G$4:$G$1003,'Time Entry'!$C$4:$C$1003,Employees!$B$7,'Time Entry'!$H$4:$H$1003,"Yes")) | D7: =IF(Employees!$B$7="","",B7-C7) | E7: =IF(OR(Employees!$B$7="",B7=0),"",C7/B7) | F7: =IF(Employees!$B$7="","",Employees!$G$7) | G7: =IF(Employees!$B$7="","",SUMIFS('Time Entry'!$J$4:$J$1003,'Time Entry'!$C$4:$C$1003,Employees!$B$7))
A8: =IF(Employees!$B$8="","",Employees!$B$8) | B8: =IF(Employees!$B$8="","",SUMIFS('Time Entry'!$G$4:$G$1003,'Time Entry'!$C$4:$C$1003,Employees!$B$8)) | C8: =IF(Employees!$B$8="","",SUMIFS('Time Entry'!$G$4:$G$1003,'Time Entry'!$C$4:$C$1003,Employees!$B$8,'Time Entry'!$H$4:$H$1003,"Yes")) | D8: =IF(Employees!$B$8="","",B8-C8) | E8: =IF(OR(Employees!$B$8="",B8=0),"",C8/B8) | F8: =IF(Employees!$B$8="","",Employees!$G$8) | G8: =IF(Employees!$B$8="","",SUMIFS('Time Entry'!$J$4:$J$1003,'Time Entry'!$C$4:$C$1003,Employees!$B$8))
A9: =IF(Employees!$B$9="","",Employees!$B$9) | B9: =IF(Employees!$B$9="","",SUMIFS('Time Entry'!$G$4:$G$1003,'Time Entry'!$C$4:$C$1003,Employees!$B$9)) | C9: =IF(Employees!$B$9="","",SUMIFS('Time Entry'!$G$4:$G$1003,'Time Entry'!$C$4:$C$1003,Employees!$B$9,'Time Entry'!$H$4:$H$1003,"Yes")) | D9: =IF(Employees!$B$9="","",B9-C9) | E9: =IF(OR(Employees!$B$9="",B9=0),"",C9/B9) | F9: =IF(Employees!$B$9="","",Employees!$G$9) | G9: =IF(Employees!$B$9="","",SUMIFS('Time Entry'!$J$4:$J$1003,'Time Entry'!$C$4:$C$1003,Employees!$B$9))
A10: =IF(Employees!$B$10="","",Employees!$B$10) | B10: =IF(Employees!$B$10="","",SUMIFS('Time Entry'!$G$4:$G$1003,'Time Entry'!$C$4:$C$1003,Employees!$B$10)) | C10: =IF(Employees!$B$10="","",SUMIFS('Time Entry'!$G$4:$G$1003,'Time Entry'!$C$4:$C$1003,Employees!$B$10,'Time Entry'!$H$4:$H$1003,"Yes")) | D10: =IF(Employees!$B$10="","",B10-C10) | E10: =IF(OR(Employees!$B$10="",B10=0),"",C10/B10) | F10: =IF(Employees!$B$10="","",Employees!$G$10) | G10: =IF(Employees!$B$10="","",SUMIFS('Time Entry'!$J$4:$J$1003,'Time Entry'!$C$4:$C$1003,Employees!$B$10))
A11: =IF(Employees!$B$11="","",Employees!$B$11) | B11: =IF(Employees!$B$11="","",SUMIFS('Time Entry'!$G$4:$G$1003,'Time Entry'!$C$4:$C$1003,Employees!$B$11)) | C11: =IF(Employees!$B$11="","",SUMIFS('Time Entry'!$G$4:$G$1003,'Time Entry'!$C$4:$C$1003,Employees!$B$11,'Time Entry'!$H$4:$H$1003,"Yes")) | D11: =IF(Employees!$B$11="","",B11-C11) | E11: =IF(OR(Employees!$B$11="",B11=0),"",C11/B11) | F11: =IF(Employees!$B$11="","",Employees!$G$11) | G11: =IF(Employees!$B$11="","",SUMIFS('Time Entry'!$J$4:$J$1003,'Time Entry'!$C$4:$C$1003,Employees!$B$11))
A12: =IF(Employees!$B$12="","",Employees!$B$12) | B12: =IF(Employees!$B$12="","",SUMIFS('Time Entry'!$G$4:$G$1003,'Time Entry'!$C$4:$C$1003,Employees!$B$12)) | C12: =IF(Employees!$B$12="","",SUMIFS('Time Entry'!$G$4:$G$1003,'Time Entry'!$C$4:$C$1003,Employees!$B$12,'Time Entry'!$H$4:$H$1003,"Yes")) | D12: =IF(Employees!$B$12="","",B12-C12) | E12: =IF(OR(Employees!$B$12="",B12=0),"",C12/B12) | F12: =IF(Employees!$B$12="","",Employees!$G$12) | G12: =IF(Employees!$B$12="","",SUMIFS('Time Entry'!$J$4:$J$1003,'Time Entry'!$C$4:$C$1003,Employees!$B$12))
A13: =IF(Employees!$B$13="","",Employees!$B$13) | B13: =IF(Employees!$B$13="","",SUMIFS('Time Entry'!$G$4:$G$1003,'Time Entry'!$C$4:$C$1003,Employees!$B$13)) | C13: =IF(Employees!$B$13="","",SUMIFS('Time Entry'!$G$4:$G$1003,'Time Entry'!$C$4:$C$1003,Employees!$B$13,'Time Entry'!$H$4:$H$1003,"Yes")) | D13: =IF(Employees!$B$13="","",B13-C13) | E13: =IF(OR(Employees!$B$13="",B13=0),"",C13/B13) | F13: =IF(Employees!$B$13="","",Employees!$G$13) | G13: =IF(Employees!$B$13="","",SUMIFS('Time Entry'!$J$4:$J$1003,'Time Entry'!$C$4:$C$1003,Employees!$B$13))
A14: =IF(Employees!$B$14="","",Employees!$B$14) | B14: =IF(Employees!$B$14="","",SUMIFS('Time Entry'!$G$4:$G$1003,'Time Entry'!$C$4:$C$1003,Employees!$B$14)) | C14: =IF(Employees!$B$14="","",SUMIFS('Time Entry'!$G$4:$G$1003,'Time Entry'!$C$4:$C$1003,Employees!$B$14,'Time Entry'!$H$4:$H$1003,"Yes")) | D14: =IF(Employees!$B$14="","",B14-C14) | E14: =IF(OR(Employees!$B$14="",B14=0),"",C14/B14) | F14: =IF(Employees!$B$14="","",Employees!$G$14) | G14: =IF(Employees!$B$14="","",SUMIFS('Time Entry'!$J$4:$J$1003,'Time Entry'!$C$4:$C$1003,Employees!$B$14))
A15: =IF(Employees!$B$15="","",Employees!$B$15) | B15: =IF(Employees!$B$15="","",SUMIFS('Time Entry'!$G$4:$G$1003,'Time Entry'!$C$4:$C$1003,Employees!$B$15)) | C15: =IF(Employees!$B$15="","",SUMIFS('Time Entry'!$G$4:$G$1003,'Time Entry'!$C$4:$C$1003,Employees!$B$15,'Time Entry'!$H$4:$H$1003,"Yes")) | D15: =IF(Employees!$B$15="","",B15-C15) | E15: =IF(OR(Employees!$B$15="",B15=0),"",C15/B15) | F15: =IF(Employees!$B$15="","",Employees!$G$15) | G15: =IF(Employees!$B$15="","",SUMIFS('Time Entry'!$J$4:$J$1003,'Time Entry'!$C$4:$C$1003,Employees!$B$15))
A16: =IF(Employees!$B$16="","",Employees!$B$16) | B16: =IF(Employees!$B$16="","",SUMIFS('Time Entry'!$G$4:$G$1003,'Time Entry'!$C$4:$C$1003,Employees!$B$16)) | C16: =IF(Employees!$B$16="","",SUMIFS('Time Entry'!$G$4:$G$1003,'Time Entry'!$C$4:$C$1003,Employees!$B$16,'Time Entry'!$H$4:$H$1003,"Yes")) | D16: =IF(Employees!$B$16="","",B16-C16) | E16: =IF(OR(Employees!$B$16="",B16=0),"",C16/B16) | F16: =IF(Employees!$B$16="","",Employees!$G$16) | G16: =IF(Employees!$B$16="","",SUMIFS('Time Entry'!$J$4:$J$1003,'Time Entry'!$C$4:$C$1003,Employees!$B$16))
A17: =IF(Employees!$B$17="","",Employees!$B$17) | B17: =IF(Employees!$B$17="","",SUMIFS('Time Entry'!$G$4:$G$1003,'Time Entry'!$C$4:$C$1003,Employees!$B$17)) | C17: =IF(Employees!$B$17="","",SUMIFS('Time Entry'!$G$4:$G$1003,'Time Entry'!$C$4:$C$1003,Employees!$B$17,'Time Entry'!$H$4:$H$1003,"Yes")) | D17: =IF(Employees!$B$17="","",B17-C17) | E17: =IF(OR(Employees!$B$17="",B17=0),"",C17/B17) | F17: =IF(Employees!$B$17="","",Employees!$G$17) | G17: =IF(Employees!$B$17="","",SUMIFS('Time Entry'!$J$4:$J$1003,'Time Entry'!$C$4:$C$1003,Employees!$B$17))
A18: =IF(Employees!$B$18="","",Employees!$B$18) | B18: =IF(Employees!$B$18="","",SUMIFS('Time Entry'!$G$4:$G$1003,'Time Entry'!$C$4:$C$1003,Employees!$B$18)) | C18: =IF(Employees!$B$18="","",SUMIFS('Time Entry'!$G$4:$G$1003,'Time Entry'!$C$4:$C$1003,Employees!$B$18,'Time Entry'!$H$4:$H$1003,"Yes")) | D18: =IF(Employees!$B$18="","",B18-C18) | E18: =IF(OR(Employees!$B$18="",B18=0),"",C18/B18) | F18: =IF(Employees!$B$18="","",Employees!$G$18) | G18: =IF(Employees!$B$18="","",SUMIFS('Time Entry'!$J$4:$J$1003,'Time Entry'!$C$4:$C$1003,Employees!$B$18))
A19: =IF(Employees!$B$19="","",Employees!$B$19) | B19: =IF(Employees!$B$19="","",SUMIFS('Time Entry'!$G$4:$G$1003,'Time Entry'!$C$4:$C$1003,Employees!$B$19)) | C19: =IF(Employees!$B$19="","",SUMIFS('Time Entry'!$G$4:$G$1003,'Time Entry'!$C$4:$C$1003,Employees!$B$19,'Time Entry'!$H$4:$H$1003,"Yes")) | D19: =IF(Employees!$B$19="","",B19-C19) | E19: =IF(OR(Employees!$B$19="",B19=0),"",C19/B19) | F19: =IF(Employees!$B$19="","",Employees!$G$19) | G19: =IF(Employees!$B$19="","",SUMIFS('Time Entry'!$J$4:$J$1003,'Time Entry'!$C$4:$C$1003,Employees!$B$19))
A20: =IF(Employees!$B$20="","",Employees!$B$20) | B20: =IF(Employees!$B$20="","",SUMIFS('Time Entry'!$G$4:$G$1003,'Time Entry'!$C$4:$C$1003,Employees!$B$20)) | C20: =IF(Employees!$B$20="","",SUMIFS('Time Entry'!$G$4:$G$1003,'Time Entry'!$C$4:$C$1003,Employees!$B$20,'Time Entry'!$H$4:$H$1003,"Yes")) | D20: =IF(Employees!$B$20="","",B20-C20) | E20: =IF(OR(Employees!$B$20="",B20=0),"",C20/B20) | F20: =IF(Employees!$B$20="","",Employees!$G$20) | G20: =IF(Employees!$B$20="","",SUMIFS('Time Entry'!$J$4:$J$1003,'Time Entry'!$C$4:$C$1003,Employees!$B$20))
A21: =IF(Employees!$B$21="","",Employees!$B$21) | B21: =IF(Employees!$B$21="","",SUMIFS('Time Entry'!$G$4:$G$1003,'Time Entry'!$C$4:$C$1003,Employees!$B$21)) | C21: =IF(Employees!$B$21="","",SUMIFS('Time Entry'!$G$4:$G$1003,'Time Entry'!$C$4:$C$1003,Employees!$B$21,'Time Entry'!$H$4:$H$1003,"Yes")) | D21: =IF(Employees!$B$21="","",B21-C21) | E21: =IF(OR(Employees!$B$21="",B21=0),"",C21/B21) | F21: =IF(Employees!$B$21="","",Employees!$G$21) | G21: =IF(Employees!$B$21="","",SUMIFS('Time Entry'!$J$4:$J$1003,'Time Entry'!$C$4:$C$1003,Employees!$B$21))
A22: =IF(Employees!$B$22="","",Employees!$B$22) | B22: =IF(Employees!$B$22="","",SUMIFS('Time Entry'!$G$4:$G$1003,'Time Entry'!$C$4:$C$1003,Employees!$B$22)) | C22: =IF(Employees!$B$22="","",SUMIFS('Time Entry'!$G$4:$G$1003,'Time Entry'!$C$4:$C$1003,Employees!$B$22,'Time Entry'!$H$4:$H$1003,"Yes")) | D22: =IF(Employees!$B$22="","",B22-C22) | E22: =IF(OR(Employees!$B$22="",B22=0),"",C22/B22) | F22: =IF(Employees!$B$22="","",Employees!$G$22) | G22: =IF(Employees!$B$22="","",SUMIFS('Time Entry'!$J$4:$J$1003,'Time Entry'!$C$4:$C$1003,Employees!$B$22))
A23: =IF(Employees!$B$23="","",Employees!$B$23) | B23: =IF(Employees!$B$23="","",SUMIFS('Time Entry'!$G$4:$G$1003,'Time Entry'!$C$4:$C$1003,Employees!$B$23)) | C23: =IF(Employees!$B$23="","",SUMIFS('Time Entry'!$G$4:$G$1003,'Time Entry'!$C$4:$C$1003,Employees!$B$23,'Time Entry'!$H$4:$H$1003,"Yes")) | D23: =IF(Employees!$B$23="","",B23-C23) | E23: =IF(OR(Employees!$B$23="",B23=0),"",C23/B23) | F23: =IF(Employees!$B$23="","",Employees!$G$23) | G23: =IF(Employees!$B$23="","",SUMIFS('Time Entry'!$J$4:$J$1003,'Time Entry'!$C$4:$C$1003,Employees!$B$23))
A24: =IF(Employees!$B$24="","",Employees!$B$24) | B24: =IF(Employees!$B$24="","",SUMIFS('Time Entry'!$G$4:$G$1003,'Time Entry'!$C$4:$C$1003,Employees!$B$24)) | C24: =IF(Employees!$B$24="","",SUMIFS('Time Entry'!$G$4:$G$1003,'Time Entry'!$C$4:$C$1003,Employees!$B$24,'Time Entry'!$H$4:$H$1003,"Yes")) | D24: =IF(Employees!$B$24="","",B24-C24) | E24: =IF(OR(Employees!$B$24="",B24=0),"",C24/B24) | F24: =IF(Employees!$B$24="","",Employees!$G$24) | G24: =IF(Employees!$B$24="","",SUMIFS('Time Entry'!$J$4:$J$1003,'Time Entry'!$C$4:$C$1003,Employees!$B$24))
A25: =IF(Employees!$B$25="","",Employees!$B$25) | B25: =IF(Employees!$B$25="","",SUMIFS('Time Entry'!$G$4:$G$1003,'Time Entry'!$C$4:$C$1003,Employees!$B$25)) | C25: =IF(Employees!$B$25="","",SUMIFS('Time Entry'!$G$4:$G$1003,'Time Entry'!$C$4:$C$1003,Employees!$B$25,'Time Entry'!$H$4:$H$1003,"Yes")) | D25: =IF(Employees!$B$25="","",B25-C25) | E25: =IF(OR(Employees!$B$25="",B25=0),"",C25/B25) | F25: =IF(Employees!$B$25="","",Employees!$G$25) | G25: =IF(Employees!$B$25="","",SUMIFS('Time Entry'!$J$4:$J$1003,'Time Entry'!$C$4:$C$1003,Employees!$B$25))
A26: =IF(Employees!$B$26="","",Employees!$B$26) | B26: =IF(Employees!$B$26="","",SUMIFS('Time Entry'!$G$4:$G$1003,'Time Entry'!$C$4:$C$1003,Employees!$B$26)) | C26: =IF(Employees!$B$26="","",SUMIFS('Time Entry'!$G$4:$G$1003,'Time Entry'!$C$4:$C$1003,Employees!$B$26,'Time Entry'!$H$4:$H$1003,"Yes")) | D26: =IF(Employees!$B$26="","",B26-C26) | E26: =IF(OR(Employees!$B$26="",B26=0),"",C26/B26) | F26: =IF(Employees!$B$26="","",Employees!$G$26) | G26: =IF(Employees!$B$26="","",SUMIFS('Time Entry'!$J$4:$J$1003,'Time Entry'!$C$4:$C$1003,Employees!$B$26))
A27: =IF(Employees!$B$27="","",Employees!$B$27) | B27: =IF(Employees!$B$27="","",SUMIFS('Time Entry'!$G$4:$G$1003,'Time Entry'!$C$4:$C$1003,Employees!$B$27)) | C27: =IF(Employees!$B$27="","",SUMIFS('Time Entry'!$G$4:$G$1003,'Time Entry'!$C$4:$C$1003,Employees!$B$27,'Time Entry'!$H$4:$H$1003,"Yes")) | D27: =IF(Employees!$B$27="","",B27-C27) | E27: =IF(OR(Employees!$B$27="",B27=0),"",C27/B27) | F27: =IF(Employees!$B$27="","",Employees!$G$27) | G27: =IF(Employees!$B$27="","",SUMIFS('Time Entry'!$J$4:$J$1003,'Time Entry'!$C$4:$C$1003,Employees!$B$27))
A28: =IF(Employees!$B$28="","",Employees!$B$28) | B28: =IF(Employees!$B$28="","",SUMIFS('Time Entry'!$G$4:$G$1003,'Time Entry'!$C$4:$C$1003,Employees!$B$28)) | C28: =IF(Employees!$B$28="","",SUMIFS('Time Entry'!$G$4:$G$1003,'Time Entry'!$C$4:$C$1003,Employees!$B$28,'Time Entry'!$H$4:$H$1003,"Yes")) | D28: =IF(Employees!$B$28="","",B28-C28) | E28: =IF(OR(Employees!$B$28="",B28=0),"",C28/B28) | F28: =IF(Employees!$B$28="","",Employees!$G$28) | G28: =IF(Employees!$B$28="","",SUMIFS('Time Entry'!$J$4:$J$1003,'Time Entry'!$C$4:$C$1003,Employees!$B$28))
A29: =IF(Employees!$B$29="","",Employees!$B$29) | B29: =IF(Employees!$B$29="","",SUMIFS('Time Entry'!$G$4:$G$1003,'Time Entry'!$C$4:$C$1003,Employees!$B$29)) | C29: =IF(Employees!$B$29="","",SUMIFS('Time Entry'!$G$4:$G$1003,'Time Entry'!$C$4:$C$1003,Employees!$B$29,'Time Entry'!$H$4:$H$1003,"Yes")) | D29: =IF(Employees!$B$29="","",B29-C29) | E29: =IF(OR(Employees!$B$29="",B29=0),"",C29/B29) | F29: =IF(Employees!$B$29="","",Employees!$G$29) | G29: =IF(Employees!$B$29="","",SUMIFS('Time Entry'!$J$4:$J$1003,'Time Entry'!$C$4:$C$1003,Employees!$B$29))
A30: =IF(Employees!$B$30="","",Employees!$B$30) | B30: =IF(Employees!$B$30="","",SUMIFS('Time Entry'!$G$4:$G$1003,'Time Entry'!$C$4:$C$1003,Employees!$B$30)) | C30: =IF(Employees!$B$30="","",SUMIFS('Time Entry'!$G$4:$G$1003,'Time Entry'!$C$4:$C$1003,Employees!$B$30,'Time Entry'!$H$4:$H$1003,"Yes")) | D30: =IF(Employees!$B$30="","",B30-C30) | E30: =IF(OR(Employees!$B$30="",B30=0),"",C30/B30) | F30: =IF(Employees!$B$30="","",Employees!$G$30) | G30: =IF(Employees!$B$30="","",SUMIFS('Time Entry'!$J$4:$J$1003,'Time Entry'!$C$4:$C$1003,Employees!$B$30))
A31: =IF(Employees!$B$31="","",Employees!$B$31) | B31: =IF(Employees!$B$31="","",SUMIFS('Time Entry'!$G$4:$G$1003,'Time Entry'!$C$4:$C$1003,Employees!$B$31)) | C31: =IF(Employees!$B$31="","",SUMIFS('Time Entry'!$G$4:$G$1003,'Time Entry'!$C$4:$C$1003,Employees!$B$31,'Time Entry'!$H$4:$H$1003,"Yes")) | D31: =IF(Employees!$B$31="","",B31-C31) | E31: =IF(OR(Employees!$B$31="",B31=0),"",C31/B31) | F31: =IF(Employees!$B$31="","",Employees!$G$31) | G31: =IF(Employees!$B$31="","",SUMIFS('Time Entry'!$J$4:$J$1003,'Time Entry'!$C$4:$C$1003,Employees!$B$31))
A32: =IF(Employees!$B$32="","",Employees!$B$32) | B32: =IF(Employees!$B$32="","",SUMIFS('Time Entry'!$G$4:$G$1003,'Time Entry'!$C$4:$C$1003,Employees!$B$32)) | C32: =IF(Employees!$B$32="","",SUMIFS('Time Entry'!$G$4:$G$1003,'Time Entry'!$C$4:$C$1003,Employees!$B$32,'Time Entry'!$H$4:$H$1003,"Yes")) | D32: =IF(Employees!$B$32="","",B32-C32) | E32: =IF(OR(Employees!$B$32="",B32=0),"",C32/B32) | F32: =IF(Employees!$B$32="","",Employees!$G$32) | G32: =IF(Employees!$B$32="","",SUMIFS('Time Entry'!$J$4:$J$1003,'Time Entry'!$C$4:$C$1003,Employees!$B$32))
A33: =IF(Employees!$B$33="","",Employees!$B$33) | B33: =IF(Employees!$B$33="","",SUMIFS('Time Entry'!$G$4:$G$1003,'Time Entry'!$C$4:$C$1003,Employees!$B$33)) | C33: =IF(Employees!$B$33="","",SUMIFS('Time Entry'!$G$4:$G$1003,'Time Entry'!$C$4:$C$1003,Employees!$B$33,'Time Entry'!$H$4:$H$1003,"Yes")) | D33: =IF(Employees!$B$33="","",B33-C33) | E33: =IF(OR(Employees!$B$33="",B33=0),"",C33/B33) | F33: =IF(Employees!$B$33="","",Employees!$G$33) | G33: =IF(Employees!$B$33="","",SUMIFS('Time Entry'!$J$4:$J$1003,'Time Entry'!$C$4:$C$1003,Employees!$B$33))
A34: =IF(Employees!$B$34="","",Employees!$B$34) | B34: =IF(Employees!$B$34="","",SUMIFS('Time Entry'!$G$4:$G$1003,'Time Entry'!$C$4:$C$1003,Employees!$B$34)) | C34: =IF(Employees!$B$34="","",SUMIFS('Time Entry'!$G$4:$G$1003,'Time Entry'!$C$4:$C$1003,Employees!$B$34,'Time Entry'!$H$4:$H$1003,"Yes")) | D34: =IF(Employees!$B$34="","",B34-C34) | E34: =IF(OR(Employees!$B$34="",B34=0),"",C34/B34) | F34: =IF(Employees!$B$34="","",Employees!$G$34) | G34: =IF(Employees!$B$34="","",SUMIFS('Time Entry'!$J$4:$J$1003,'Time Entry'!$C$4:$C$1003,Employees!$B$34))
A35: =IF(Employees!$B$35="","",Employees!$B$35) | B35: =IF(Employees!$B$35="","",SUMIFS('Time Entry'!$G$4:$G$1003,'Time Entry'!$C$4:$C$1003,Employees!$B$35)) | C35: =IF(Employees!$B$35="","",SUMIFS('Time Entry'!$G$4:$G$1003,'Time Entry'!$C$4:$C$1003,Employees!$B$35,'Time Entry'!$H$4:$H$1003,"Yes")) | D35: =IF(Employees!$B$35="","",B35-C35) | E35: =IF(OR(Employees!$B$35="",B35=0),"",C35/B35) | F35: =IF(Employees!$B$35="","",Employees!$G$35) | G35: =IF(Employees!$B$35="","",SUMIFS('Time Entry'!$J$4:$J$1003,'Time Entry'!$C$4:$C$1003,Employees!$B$35))
A36: =IF(Employees!$B$36="","",Employees!$B$36) | B36: =IF(Employees!$B$36="","",SUMIFS('Time Entry'!$G$4:$G$1003,'Time Entry'!$C$4:$C$1003,Employees!$B$36)) | C36: =IF(Employees!$B$36="","",SUMIFS('Time Entry'!$G$4:$G$1003,'Time Entry'!$C$4:$C$1003,Employees!$B$36,'Time Entry'!$H$4:$H$1003,"Yes")) | D36: =IF(Employees!$B$36="","",B36-C36) | E36: =IF(OR(Employees!$B$36="",B36=0),"",C36/B36) | F36: =IF(Employees!$B$36="","",Employees!$G$36) | G36: =IF(Employees!$B$36="","",SUMIFS('Time Entry'!$J$4:$J$1003,'Time Entry'!$C$4:$C$1003,Employees!$B$36))
A37: =IF(Employees!$B$37="","",Employees!$B$37) | B37: =IF(Employees!$B$37="","",SUMIFS('Time Entry'!$G$4:$G$1003,'Time Entry'!$C$4:$C$1003,Employees!$B$37)) | C37: =IF(Employees!$B$37="","",SUMIFS('Time Entry'!$G$4:$G$1003,'Time Entry'!$C$4:$C$1003,Employees!$B$37,'Time Entry'!$H$4:$H$1003,"Yes")) | D37: =IF(Employees!$B$37="","",B37-C37) | E37: =IF(OR(Employees!$B$37="",B37=0),"",C37/B37) | F37: =IF(Employees!$B$37="","",Employees!$G$37) | G37: =IF(Employees!$B$37="","",SUMIFS('Time Entry'!$J$4:$J$1003,'Time Entry'!$C$4:$C$1003,Employees!$B$37))
A38: =IF(Employees!$B$38="","",Employees!$B$38) | B38: =IF(Employees!$B$38="","",SUMIFS('Time Entry'!$G$4:$G$1003,'Time Entry'!$C$4:$C$1003,Employees!$B$38)) | C38: =IF(Employees!$B$38="","",SUMIFS('Time Entry'!$G$4:$G$1003,'Time Entry'!$C$4:$C$1003,Employees!$B$38,'Time Entry'!$H$4:$H$1003,"Yes")) | D38: =IF(Employees!$B$38="","",B38-C38) | E38: =IF(OR(Employees!$B$38="",B38=0),"",C38/B38) | F38: =IF(Employees!$B$38="","",Employees!$G$38) | G38: =IF(Employees!$B$38="","",SUMIFS('Time Entry'!$J$4:$J$1003,'Time Entry'!$C$4:$C$1003,Employees!$B$38))
A39: =IF(Employees!$B$39="","",Employees!$B$39) | B39: =IF(Employees!$B$39="","",SUMIFS('Time Entry'!$G$4:$G$1003,'Time Entry'!$C$4:$C$1003,Employees!$B$39)) | C39: =IF(Employees!$B$39="","",SUMIFS('Time Entry'!$G$4:$G$1003,'Time Entry'!$C$4:$C$1003,Employees!$B$39,'Time Entry'!$H$4:$H$1003,"Yes")) | D39: =IF(Employees!$B$39="","",B39-C39) | E39: =IF(OR(Employees!$B$39="",B39=0),"",C39/B39) | F39: =IF(Employees!$B$39="","",Employees!$G$39) | G39: =IF(Employees!$B$39="","",SUMIFS('Time Entry'!$J$4:$J$1003,'Time Entry'!$C$4:$C$1003,Employees!$B$39))
A40: =IF(Employees!$B$40="","",Employees!$B$40) | B40: =IF(Employees!$B$40="","",SUMIFS('Time Entry'!$G$4:$G$1003,'Time Entry'!$C$4:$C$1003,Employees!$B$40)) | C40: =IF(Employees!$B$40="","",SUMIFS('Time Entry'!$G$4:$G$1003,'Time Entry'!$C$4:$C$1003,Employees!$B$40,'Time Entry'!$H$4:$H$1003,"Yes")) | D40: =IF(Employees!$B$40="","",B40-C40) | E40: =IF(OR(Employees!$B$40="",B40=0),"",C40/B40) | F40: =IF(Employees!$B$40="","",Employees!$G$40) | G40: =IF(Employees!$B$40="","",SUMIFS('Time Entry'!$J$4:$J$1003,'Time Entry'!$C$4:$C$1003,Employees!$B$40))
...

Sheet Invoices
A1: Invoices
A2: Register of invoices raised. Pick the Project to see its unbilled WIP on the right, then enter the invoice amount.
